[2024-03-10T09:53:52.503+0000] {taskinstance.py:1979} INFO - Dependencies all met for dep_context=non-requeueable deps ti=<TaskInstance: task1_v5.download_and_zip_files manual__2024-03-10T09:53:10.637789+00:00 [queued]>
[2024-03-10T09:53:52.633+0000] {taskinstance.py:1979} INFO - Dependencies all met for dep_context=requeueable deps ti=<TaskInstance: task1_v5.download_and_zip_files manual__2024-03-10T09:53:10.637789+00:00 [queued]>
[2024-03-10T09:53:52.633+0000] {taskinstance.py:2193} INFO - Starting attempt 1 of 2
[2024-03-10T09:53:52.760+0000] {taskinstance.py:2214} INFO - Executing <Task(PythonOperator): download_and_zip_files> on 2024-03-10 09:53:10.637789+00:00
[2024-03-10T09:53:52.769+0000] {standard_task_runner.py:60} INFO - Started process 1273 to run task
[2024-03-10T09:53:52.773+0000] {standard_task_runner.py:87} INFO - Running: ['airflow', 'tasks', 'run', 'task1_v5', 'download_and_zip_files', 'manual__2024-03-10T09:53:10.637789+00:00', '--job-id', '17', '--raw', '--subdir', 'DAGS_FOLDER/task1_v5.py', '--cfg-path', '/tmp/tmppfy6i9eo']
[2024-03-10T09:53:52.776+0000] {standard_task_runner.py:88} INFO - Job 17: Subtask download_and_zip_files
[2024-03-10T09:53:53.084+0000] {task_command.py:423} INFO - Running <TaskInstance: task1_v5.download_and_zip_files manual__2024-03-10T09:53:10.637789+00:00 [running]> on host 4dfa689a22dd
[2024-03-10T09:53:53.512+0000] {taskinstance.py:2510} INFO - Exporting env vars: AIRFLOW_CTX_DAG_OWNER='airflow' AIRFLOW_CTX_DAG_ID='task1_v5' AIRFLOW_CTX_TASK_ID='download_and_zip_files' AIRFLOW_CTX_EXECUTION_DATE='2024-03-10T09:53:10.637789+00:00' AIRFLOW_CTX_TRY_NUMBER='1' AIRFLOW_CTX_DAG_RUN_ID='manual__2024-03-10T09:53:10.637789+00:00'
[2024-03-10T09:53:53.528+0000] {taskinstance.py:2728} ERROR - Task failed with exception
Traceback (most recent call last):
  File "/home/airflow/.local/lib/python3.11/site-packages/airflow/models/taskinstance.py", line 444, in _execute_task
    result = _execute_callable(context=context, **execute_callable_kwargs)
             ^^^^^^^^^^^^^^^^^^^^^^^^^^^^^^^^^^^^^^^^^^^^^^^^^^^^^^^^^^^^^
  File "/home/airflow/.local/lib/python3.11/site-packages/airflow/models/taskinstance.py", line 414, in _execute_callable
    return execute_callable(context=context, **execute_callable_kwargs)
           ^^^^^^^^^^^^^^^^^^^^^^^^^^^^^^^^^^^^^^^^^^^^^^^^^^^^^^^^^^^^
  File "/home/airflow/.local/lib/python3.11/site-packages/airflow/operators/python.py", line 200, in execute
    return_value = self.execute_callable()
                   ^^^^^^^^^^^^^^^^^^^^^^^
  File "/home/airflow/.local/lib/python3.11/site-packages/airflow/operators/python.py", line 217, in execute_callable
    return self.python_callable(*self.op_args, **self.op_kwargs)
           ^^^^^^^^^^^^^^^^^^^^^^^^^^^^^^^^^^^^^^^^^^^^^^^^^^^^^
  File "/opt/airflow/dags/task1_v5.py", line 50, in download_and_zip_files
    with zipfile.ZipFile(zip_file_path, 'w') as zipf:
         ^^^^^^^^^^^^^^^^^^^^^^^^^^^^^^^^^^^
  File "/usr/local/lib/python3.11/zipfile.py", line 1286, in __init__
    self.fp = io.open(file, filemode)
              ^^^^^^^^^^^^^^^^^^^^^^^
FileNotFoundError: [Errno 2] No such file or directory: '/tmp/archives/2023_data.zip'
[2024-03-10T09:53:53.543+0000] {taskinstance.py:1149} INFO - Marking task as UP_FOR_RETRY. dag_id=task1_v5, task_id=download_and_zip_files, execution_date=20240310T095310, start_date=20240310T095352, end_date=20240310T095353
[2024-03-10T09:53:53.688+0000] {standard_task_runner.py:107} ERROR - Failed to execute job 17 for task download_and_zip_files ([Errno 2] No such file or directory: '/tmp/archives/2023_data.zip'; 1273)
[2024-03-10T09:53:53.718+0000] {local_task_job_runner.py:234} INFO - Task exited with return code 1
[2024-03-10T09:53:53.745+0000] {taskinstance.py:3309} INFO - 0 downstream tasks scheduled from follow-on schedule check
